Workbook

Sheet Run_Plan
A1: Run Number | B1: R6-C1-S1
A2: Run Objective | F2: What's New in V1.2 ? : • Automatic GC injection time check is implemented • Automatic outlier highlighting for GC data
A3: Run Start Date | B3: 45425.583
A4: Lab Notebook Reference
A6: Catalyst Loading Plan - Proposed and Actual Weights of Catalysts
A7: Physical Form Loaded | B7: Crushed and sieved, 355-212 microns
B8: R1 | C8: Weight Loaded [mg] | E8: Actual Volume [mL] | F8: R2 | G8: Weight Loaded [mg] | I8: Actual Volume [mL] | J8: R3 | K8: Weight Loaded [mg] | M8: Actual Volume [mL] | N8: R4 | O8: Weight Loaded [mg] | Q8: Actual Volume [mL]
B9: Catalyst ID | C9: Target | D9: Actual | F9: Catalyst ID | G9: Target | H9: Actual | J9: Catalyst ID | K9: Target | L9: Actual | N9: Catalyst ID | O9: Target | P9: Actual
A10: Top Bed | B10: Ni2CBV-3014 | C10: 1767 | D10: 1768 | E10: 3 | F10: Ni5CBV-3014 | G10: 1875 | H10: 1876 | I10: 3 | N10: Cu5CBV500 | O10: 1677 | P10: 1677 | Q10: 3
A11: Middle Bed
A12: Bottom Bed
A13: Total weight or volume | C13: =SUM(C10:C12) -> 1767 | D13: =SUM(D10:D12) -> 1768 | E13: =SUM(E10:E12) -> 3 | G13: =SUM(G10:G12) -> 1875 | H13: =SUM(H10:H12) -> 1876 | I13: =SUM(I10:I12) -> 3 | K13: =SUM(K10:K12) -> 0 | L13: =SUM(L10:L12) -> 0 | M13: =SUM(M10:M12) -> 0 | O13: =SUM(O10:O12) -> 1677 | P13: =SUM(P10:P12) -> 1677 | Q13: =SUM(Q10:Q12) -> 3
A14: Condensed Cat Description | B14: =IF(OR(B12="", B12="-"), IF(OR(B11="", B11="-"), IF(B10="", "", CONCATENATE(B8, " Catalyst ", B10)), CONCATENATE(B8, " Catalyst ",B10, " / ", B11)),CONCATENATE(B8, " Catalyst ",B10, " / ", B11, " / ", B12)) -> R1 Catalyst Ni2CBV-3014 | F14: =IF(OR(F12="", F12="-"), IF(OR(F11="", F11="-"), IF(F10="", "", CONCATENATE(F8, " Catalyst ", F10)), CONCATENATE(F8, " Catalyst ",F10, " / ", F11)),CONCATENATE(F8, " Catalyst ",F10, " / ", F11, " / ", F12)) -> R2 Catalyst Ni5CBV-3014 | J14: =IF(OR(J12="", J12="-"), IF(OR(J11="", J11="-"), IF(J10="", "", CONCATENATE(J8, " Catalyst ", J10)), CONCATENATE(J8, " Catalyst ",J10, " / ", J11)),CONCATENATE(J8, " Catalyst ",J10, " / ", J11, " / ", J12)) | N14: =IF(OR(N12="", N12="-"), IF(OR(N11="", N11="-"), IF(N10="", "", CONCATENATE(N8, " Catalyst ", N10)), CONCATENATE(N8, " Catalyst ",N10, " / ", N11)),CONCATENATE(N8, " Catalyst ",N10, " / ", N11, " / ", N12)) -> R4 Catalyst Cu5CBV500
B15: R5 | C15: Weight Loaded [mg] | E15: Actual Volume [mL] | F15: R6 | G15: Weight Loaded [mg] | I15: Actual Volume [mL] | J15: R7 | K15: Weight Loaded [mg] | M15: Actual Volume [mL] | N15: R8 | O15: Weight Loaded [mg] | Q15: Actual Volume [mL]
B16: Catalyst ID | C16: Target | D16: Actual | F16: Catalyst ID | G16: Target | H16: Actual | J16: Catalyst ID | K16: Target | L16: Actual | N16: Catalyst ID | O16: Target | P16: Actual
A17: Top Bed | B17: alpha-Alumina | C17: 3825.6 | F17: Cu5CBV720 | G17: 1410 | H17: 1411 | I17: 3 | J17: Ni2CBV-3014 | K17: 1767 | L17: 1771 | M17: 3 | N17: Ni5CBV500 | O17: 1710 | P17: 1713 | Q17: 3
A18: Middle Bed
A19: Bottom Bed
A20: Total weight [mg] | C20: =SUM(C17:C19) -> 3825.6 | D20: =SUM(D17:D19) -> 0 | E20: =SUM(E17:E19) -> 0 | G20: =SUM(G17:G19) -> 1410 | H20: =SUM(H17:H19) -> 1411 | I20: =SUM(I17:I19) -> 3 | K20: =SUM(K17:K19) -> 1767 | L20: =SUM(L17:L19) -> 1771 | M20: =SUM(M17:M19) -> 3 | O20: =SUM(O17:O19) -> 1710 | P20: =SUM(P17:P19) -> 1713 | Q20: =SUM(Q17:Q19) -> 3
A21: Condensed Cat Description | B21: =IF(OR(B19="", B19="-"), IF(OR(B18="", B18="-"), IF(B17="", "", CONCATENATE(B15, " Catalyst ", B17)), CONCATENATE(B15, " Catalyst ",B17, " / ", B18)),CONCATENATE(B15, " Catalyst ",B17, " / ", B18, " / ", B19)) -> R5 Catalyst alpha-Alumina | F21: =IF(OR(F19="", F19="-"), IF(OR(F18="", F18="-"), IF(F17="", "", CONCATENATE(F15, " Catalyst ", F17)), CONCATENATE(F15, " Catalyst ",F17, " / ", F18)),CONCATENATE(F15, " Catalyst ",F17, " / ", F18, " / ", F19)) -> R6 Catalyst Cu5CBV720 | J21: =IF(OR(J19="", J19="-"), IF(OR(J18="", J18="-"), IF(J17="", "", CONCATENATE(J15, " Catalyst ", J17)), CONCATENATE(J15, " Catalyst ",J17, " / ", J18)),CONCATENATE(J15, " Catalyst ",J17, " / ", J18, " / ", J19)) -> R7 Catalyst Ni2CBV-3014 | N21: =IF(OR(N19="", N19="-"), IF(OR(N18="", N18="-"), IF(N17="", "", CONCATENATE(N15, " Catalyst ", N17)), CONCATENATE(N15, " Catalyst ",N17, " / ", N18)),CONCATENATE(N15, " Catalyst ",N17, " / ", N18, " / ", N19)) -> R8 Catalyst Ni5CBV500
A23: Target Feed Gas Composition | N23: Vacuum Criteria Checked and Met? | O23: Yes | P23: No
A24: Gas | B24: Hydrogen | C24: Ethylene | D24: Methane | E24: Ethane | F24: Nitrogen | G24: CO2 | H24: CO | I24: Argon | J24: Mixed gas | K24: Total mol% | L24: Total Flow | M24: Gas Density | O24: Hydrogen | P24: Argon | Q24: Methane | R24: CO | S24: CO2 | T24: Ethane | U24: Ethylene | V24: Nitrogen | W24: Mixed gas | X24: Total
A25: Used for GoR or GHSV Calc? | I25: Yes | J25: Yes | L25: Nl/h | M25: 0.9014
A26: Condition-1 [mol%] | I26: 5 | J26: 95 | K26: 100 | N26: Yes | O26: =IF(B$25="Yes", B26, 0) -> 0 | P26: =IF(C$25="Yes", C26, 0) -> 0 | Q26: =IF(D$25="Yes", D26, 0) -> 0 | R26: =IF(E$25="Yes", E26, 0) -> 0 | S26: =IF(F$25="Yes", F26, 0) -> 0 | T26: =IF(G$25="Yes", G26, 0) -> 0 | U26: =IF(H$25="Yes", H26, 0) -> 0 | V26: =IF(I$25="Yes", I26, 0) -> 5 | W26: =IF(J$25="Yes", J26, 0) -> 95 | X26: =SUM(O26:W26) -> 100
A27: Condition-2 [mol%] | I27: 5 | J27: 95 | K27: 100 | N27: Yes | O27: =IF(B$25="Yes", B27, 0) -> 0 | P27: =IF(C$25="Yes", C27, 0) -> 0 | Q27: =IF(D$25="Yes", D27, 0) -> 0 | R27: =IF(E$25="Yes", E27, 0) -> 0 | S27: =IF(F$25="Yes", F27, 0) -> 0 | T27: =IF(G$25="Yes", G27, 0) -> 0 | U27: =IF(H$25="Yes", H27, 0) -> 0 | V27: =IF(I$25="Yes", I27, 0) -> 5 | W27: =IF(J$25="Yes", J27, 0) -> 95 | X27: =SUM(O27:W27) -> 100
A28: Condition-3 [mol%] | I28: 5 | J28: 95 | K28: 100 | N28: Yes | O28: =IF(B$25="Yes", B28, 0) -> 0 | P28: =IF(C$25="Yes", C28, 0) -> 0 | Q28: =IF(D$25="Yes", D28, 0) -> 0 | R28: =IF(E$25="Yes", E28, 0) -> 0 | S28: =IF(F$25="Yes", F28, 0) -> 0 | T28: =IF(G$25="Yes", G28, 0) -> 0 | U28: =IF(H$25="Yes", H28, 0) -> 0 | V28: =IF(I$25="Yes", I28, 0) -> 5 | W28: =IF(J$25="Yes", J28, 0) -> 95 | X28: =SUM(O28:W28) -> 100
A29: Condition-4 [mol%] | I29: 5 | J29: 95 | K29: 100 | N29: Yes | O29: =IF(B$25="Yes", B29, 0) -> 0 | P29: =IF(C$25="Yes", C29, 0) -> 0 | Q29: =IF(D$25="Yes", D29, 0) -> 0 | R29: =IF(E$25="Yes", E29, 0) -> 0 | S29: =IF(F$25="Yes", F29, 0) -> 0 | T29: =IF(G$25="Yes", G29, 0) -> 0 | U29: =IF(H$25="Yes", H29, 0) -> 0 | V29: =IF(I$25="Yes", I29, 0) -> 5 | W29: =IF(J$25="Yes", J29, 0) -> 95 | X29: =SUM(O29:W29) -> 100
A30: Condition-5 [mol%] | I30: 5 | J30: 95 | K30: 100 | N30: Yes | O30: =IF(B$25="Yes", B30, 0) -> 0 | P30: =IF(C$25="Yes", C30, 0) -> 0 | Q30: =IF(D$25="Yes", D30, 0) -> 0 | R30: =IF(E$25="Yes", E30, 0) -> 0 | S30: =IF(F$25="Yes", F30, 0) -> 0 | T30: =IF(G$25="Yes", G30, 0) -> 0 | U30: =IF(H$25="Yes", H30, 0) -> 0 | V30: =IF(I$25="Yes", I30, 0) -> 5 | W30: =IF(J$25="Yes", J30, 0) -> 95 | X30: =SUM(O30:W30) -> 100
A31: Condition-6 [mol%] | I31: 5 | J31: 95 | K31: 100 | N31: Yes | O31: =IF(B$25="Yes", B31, 0) -> 0 | P31: =IF(C$25="Yes", C31, 0) -> 0 | Q31: =IF(D$25="Yes", D31, 0) -> 0 | R31: =IF(E$25="Yes", E31, 0) -> 0 | S31: =IF(F$25="Yes", F31, 0) -> 0 | T31: =IF(G$25="Yes", G31, 0) -> 0 | U31: =IF(H$25="Yes", H31, 0) -> 0 | V31: =IF(I$25="Yes", I31, 0) -> 5 | W31: =IF(J$25="Yes", J31, 0) -> 95 | X31: =SUM(O31:W31) -> 100
A33: Mixed Gas Composition (If Mixed Gas is Used, Enter Composition Information)
A34: Component | B34: Hydrogen | C34: Ethylene | D34: Methane | E34: Ethane | F34: Nitrogen | G34: CO2 | H34: CO | I34: Acetylene | J34: Propylene | K34: Propane | L34: Total
A35: Concentration [mol%] | B35: =ZMB!$B$22 -> 20.904323 | C35: =ZMB!$B$23 -> 1.6127312 | D35: =ZMB!$B$24 -> 2.5354912 | E35: =ZMB!$B$25 -> 0.0017224 | F35: =ZMB!$B$26 -> 59.79788 | G35: =ZMB!$B$27 -> 0 | H35: =ZMB!$B$28 -> 0 | I35: =ZMB!$B$29 -> 7.8221248 | J35: =ZMB!$B$30 -> 0 | K35: =ZMB!$B$31 -> 0 | L35: =SUM(B35:K35) -> 92.674272
A36: Concentration [Mass %] | B36: =IFERROR(100*B38/SUM($B$38:$K$38),"") -> 2.0998423 | C36: =IFERROR(100*C38/SUM($B$38:$K$38),"") -> 2.2543266 | D36: =IFERROR(100*D38/SUM($B$38:$K$38),"") -> 2.0267853 | E36: =IFERROR(100*E38/SUM($B$38:$K$38),"") -> 0.0025806405 | F36: =IFERROR(100*F38/SUM($B$38:$K$38),"") -> 83.468185 | G36: =IFERROR(100*G38/SUM($B$38:$K$38),"") -> 0 | H36: =IFERROR(100*H38/SUM($B$38:$K$38),"") -> 0 | I36: =IFERROR(100*I38/SUM($B$38:$K$38),"") -> 10.14828 | ... K36: =IFERROR(100*K38/SUM($B$38:$K$38),"") -> 0 | L36: =SUM(B36:K36) -> 100
A37: Mol Wt | B37: 2.016 | C37: 28.054 | D37: 16.043 | E37: 30.07 | F37: 28.014 | G37: 44.009 | H37: 28.01 | I37: 26.038 | J37: 42.081 | K37: 44.097
A38: g of Gas in 100 gmol of Gas | B38: =B35*B37 -> 42.143114 | C38: =C35*C37 -> 45.243561 | D38: =D35*D37 -> 40.676885 | E38: =E35*E37 -> 0.051792568 | F38: =F35*F37 -> 1675.1778 | G38: =G35*G37 -> 0 | H38: =H35*H37 -> 0 | I38: =I35*I37 -> 203.67249 | ... K38: =K35*K37 -> 0
A39: Carbon [Mass%] | B39: 0 | C39: 85.627718 | D39: 74.867543 | E39: 79.88693 | F39: 0 | G39: 27.292145 | H39: 42.881114 | I39: 92.25747 | J39: 85.627718 | K39: 81.713042
A40: Hydrogen [Mass%] | B40: 100 | C40: 14.372282 | D40: 25.132457 | E40: 20.11307 | F40: 0 | G40: 0 | H40: 0 | I40: 7.7425301 | J40: 14.372282 | K40: 18.286958
A41: Oxygen [Mass%] | B41: 0 | C41: 0 | D41: 0 | E41: 0 | F41: 0 | G41: 72.707855 | H41: 57.118886 | I41: 0 | J41: 0 | K41: 0
A42: Nitrogen [Mass%] | B42: 0 | C42: 0 | D42: 0 | E42: 0 | F42: 100 | G42: 0 | H42: 0 | I42: 0 | J42: 0 | K42: 0
A43: Carbon Contained in 100 kg Gas | B43: =B$36*B39/100 -> 0 | C43: =C$36*C39/100 -> 1.9303285 | D43: =D$36*D39/100 -> 1.5174044 | E43: =E$36*E39/100 -> 0.0020615945 | F43: =F$36*F39/100 -> 0 | G43: =G$36*G39/100 -> 0 | H43: =H$36*H39/100 -> 0 | I43: =I$36*I39/100 -> 9.362546 | ... K43: =K$36*K39/100 -> 0 | L43: =SUM(B43:K43) -> 12.81234
...

Sheet Liq
A1: Run Number | B1: =IF(Run_Plan!$B$1="", "", Run_Plan!$B$1) -> R6-C1-S1
A2: Run Objective | B2: =IF(Run_Plan!$B$2="", "", Run_Plan!$B$2)
A3: Run Start Date | B3: =IF(Run_Plan!$B$3="", "", Run_Plan!$B$3) -> 45425.583
A4: Condition and Sample Number | B4: C1-S1
A5: Sample Collection Started | B5: 45426.328 | C5: 45426.328 | E5: 45426.328 | F5: 45426.328 | G5: 45426.328 | H5: 45426.328 | I5: 45426.328
A6: Sample Collection Finished | B6: 45426.332 | C6: 45426.332 | E6: 45426.332 | F6: 45426.332 | G6: 45426.332 | H6: 45426.332 | I6: 45426.332
A7: Duration of Sampling | B7: =IF(OR(B5="", B6=""), "", (B6-B5)*1440) -> 6 | C7: =IF(OR(C5="", C6=""), "", (C6-C5)*1440) -> 6 | D7: =IF(OR(D5="", D6=""), "", (D6-D5)*1440) | E7: =IF(OR(E5="", E6=""), "", (E6-E5)*1440) -> 6 | F7: =IF(OR(F5="", F6=""), "", (F6-F5)*1440) -> 6 | G7: =IF(OR(G5="", G6=""), "", (G6-G5)*1440) -> 6 | H7: =IF(OR(H5="", H6=""), "", (H6-H5)*1440) -> 6 | I7: =IF(OR(I5="", I6=""), "", (I6-I5)*1440) -> 6
A8: Average Time-on-Stream | B8: =IFERROR(24*((B5+B6)/2-$B$3), "") -> 17.916667 | C8: =IFERROR(24*((C5+C6)/2-$B$3),"") -> 17.916667 | D8: =IFERROR(24*((D5+D6)/2-$B$3),"") -> -1090214 | E8: =IFERROR(24*((E5+E6)/2-$B$3),"") -> 17.916667 | F8: =IFERROR(24*((F5+F6)/2-$B$3),"") -> 17.916667 | G8: =IFERROR(24*((G5+G6)/2-$B$3),"") -> 17.916667 | H8: =IFERROR(24*((H5+H6)/2-$B$3),"") -> 17.916667 | I8: =IFERROR(24*((I5+I6)/2-$B$3),"") -> 17.916667
A10: Mass of Liquid Feed Pumped into Each Reactor Over Sampling Duration
B11: R1 | C11: R2 | D11: R3 | E11: R4 | F11: R5 | G11: R6 | H11: R7 | I11: R8
B12: 02i2FIC01 | C12: 02i2FIC02 | D12: 02i2FIC03 | E12: 02i2FIC04 | F12: 02i2FIC05 | G12: 02i2FIC06 | H12: 02i2FIC07 | I12: 02i2FIC08
A13: Feed flow rate [g/h] | B13: =ZMB!B$13 -> 0.5 | C13: =ZMB!C$13 -> 0.5 | D13: =ZMB!D$13 | E13: =ZMB!E$13 -> 0.5 | F13: =ZMB!F$13 -> 0.5 | G13: =ZMB!G$13 -> 0.5 | H13: =ZMB!H$13 -> 0.5 | I13: =ZMB!I$13 -> 0.5
A15: Mass of Total Liquid Product (TLP) and Decanted Products (If Two Phases Were Seen)
B16: R1 | C16: R2 | D16: R3 | E16: R4 | F16: R5 | G16: R6 | H16: R7 | I16: R8
A17: TLP Mass [g]
A18: Hydrocarbon (Top) Phase Mass [g]
A19: Aqueous (Bottom) Phase Mass [g]
A20: Decantation Loss [%] | B20: =IFERROR(100-100*(B18+B19)/B17,"") | C20: =IFERROR(100-100*(C18+C19)/C17,"") | D20: =IFERROR(100-100*(D18+D19)/D17,"") | E20: =IFERROR(100-100*(E18+E19)/E17,"") | F20: =IFERROR(100-100*(F18+F19)/F17,"") | G20: =IFERROR(100-100*(G18+G19)/G17,"") | H20: =IFERROR(100-100*(H18+H19)/H17,"") | I20: =IFERROR(100-100*(I18+I19)/I17,"")
A22: Elemental Analyses of Hydrocarbon Liquid Product
B23: R1 | C23: R2 | D23: R3 | E23: R4 | F23: R5 | G23: R6 | H23: R7 | I23: R8
A24: Carbon [wt%]
A25: Hydrogen [wt%]
A26: Oxygen [wt%]
A27: Nitrogen [ppmw]
A28: Sulfur [ppmw]
A30: Any Other Bulk Analyses
B31: R1 | C31: R2 | D31: R3 | E31: R4 | F31: R5 | G31: R6 | H31: R7 | I31: R8
A32: Density [g/mL]
A33: Monoaromatics by IP-391 [wt%]
A34: Diaromatics by IP-391 [wt%]
A35: Tri+aromatics by IP-391 [wt%]
A36: …
A38: Flow Rate of Hydrocarbon and Aqueous Liquid Product from Each Reactor over Sampling Duration
B39: R1 | C39: R2 | D39: R3 | E39: R4 | F39: R5 | G39: R6 | H39: R7 | I39: R8
A40: Hydrocarbon (Top) Phase Flow Rate [g/h] | B40: =IFERROR((B17-B19)/(B8),"") -> 0 | C40: =IFERROR((C17-C19)/(C8),"") -> 0 | D40: =IFERROR((D17-D19)/(D8),"") -> 0 | E40: =IFERROR((E17-E19)/(E8),"") -> 0 | F40: =IFERROR((F17-F19)/(F8),"") -> 0 | G40: =IFERROR((G17-G19)/(G8),"") -> 0 | H40: =IFERROR((H17-H19)/(H8),"") -> 0 | I40: =IFERROR((I17-I19)/(I8),"") -> 0
A41: Aqueous (Bottom) Phase Flow Rate [g/h] | B41: =IFERROR(B19/(B7/60),"") -> 0 | C41: =IFERROR(C19/(C7/60),"") -> 0 | D41: =IFERROR(D19/(D7/60),"") | E41: =IFERROR(E19/(E7/60),"") -> 0 | F41: =IFERROR(F19/(F7/60),"") -> 0 | G41: =IFERROR(G19/(G7/60),"") -> 0 | H41: =IFERROR(H19/(H7/60),"") -> 0 | I41: =IFERROR(I19/(I7/60),"") -> 0

Sheet HC_SIMDIS
C1: Boiling Point, °C | K1: Yes | L1: No
B2: Mass Recovered, % | C2: =Run_Plan!B14 -> R1 Catalyst Ni2CBV-3014 | D2: =Run_Plan!F14 -> R2 Catalyst Ni5CBV-3014 | E2: =Run_Plan!J14 | F2: =Run_Plan!N14 -> R4 Catalyst Cu5CBV500 | G2: =Run_Plan!B21 -> R5 Catalyst alpha-Alumina | H2: =Run_Plan!F21 -> R6 Catalyst Cu5CBV720 | I2: =Run_Plan!J21 -> R7 Catalyst Ni2CBV-3014 | J2: =Run_Plan!N21 -> R8 Catalyst Ni5CBV500
B3: 0.5 | M3: SIMDIS Profile for TLP-Hydrocarbon Product
B4: 1
B5: 2 | M5: Run | N5: =Liq!B1 -> R6-C1-S1 | O5: Sample | P5: =Liq!B4 -> C1-S1
B6: 3 | M6: Feedstock | N6: =Run_Plan!B49 -> Diesel (2nd stage), tol mixed
B7: 4
B8: 5
B9: 6
B10: 7
B11: 8
B12: 9
B13: 10
B14: 11
B15: 12
B16: 13
B17: 14
B18: 15
... B36: 33
B37: 34 | M37: SIMDIS Profile for TLP-Hydrocarbon Product
B38: 35
B39: 36 | M39: Run | N39: =N5 -> R6-C1-S1 | O39: Sample | P39: =P5 -> C1-S1
B40: 37 | M40: Feedstock | N40: =Run_Plan!B49 -> Diesel (2nd stage), tol mixed
B41: 38
B42: 39
B43: 40
B44: 41
B45: 42
B46: 43
B47: 44
B48: 45
B49: 46
B50: 47
B51: 48
B52: 49
... B103: 99.5

Sheet HC_DHA
B2: DHA-PIONA Reactor-1 Hydrocarbon TLP | K2: =B2 -> DHA-PIONA Reactor-1 Hydrocarbon TLP | V2: DHA-PIONA Reactor-5 Hydrocarbon TLP | AE2: =V2 -> DHA-PIONA Reactor-5 Hydrocarbon TLP
B3: Carbon Number | C3: n-Paraffins | D3: Isoparaffins | E3: Aromatics | F3: Naphthenes | G3: Olefins | H3: Oxygenates | I3: Total | V3: Carbon Number | W3: n-Paraffins | X3: Isoparaffins | Y3: Aromatics | Z3: Naphthenes | AA3: Olefins | AB3: Oxygenates | AC3: Total
B4: 1 | K4: Run | L4: =Run_Plan!B14 -> R1 Catalyst Ni2CBV-3014 | P4: Sample | Q4: =Liq!$B$4 -> C1-S1 | V4: 1 | AE4: Run | AF4: =Run_Plan!B21 -> R5 Catalyst alpha-Alumina | AJ4: Sample | AK4: =Liq!$B$4 -> C1-S1
B5: 2 | V5: 2
B6: 3 | V6: 3
B7: 4 | V7: 4
B8: 5 | V8: 5
B9: 6 | V9: 6
B10: 7 | V10: 7
B11: 8 | V11: 8
B12: 9 | V12: 9
B13: 10 | V13: 10
B14: 11 | V14: 11
B15: 12 | V15: 12
B16: 13 | V16: 13
... B18: 15 | V18: 15
B19: Total | V19: Total
H20: Total Unknowns | AB20: Total Unknowns
H21: Grand Total | AB21: Grand Total
O28: Unknowns | P28: =I20 -> 0 | AI28: Unknowns | AJ28: =AC20 -> 0
B30: DHA-PIONA Reactor-2 Hydrocarbon TLP | K30: =B30 -> DHA-PIONA Reactor-2 Hydrocarbon TLP | V30: DHA-PIONA Reactor-6 Hydrocarbon TLP | AE30: =V30 -> DHA-PIONA Reactor-6 Hydrocarbon TLP
B31: Carbon Number | C31: n-Paraffins | D31: Isoparaffins | E31: Aromatics | F31: Naphthenes | G31: Olefins | H31: Oxygenates | I31: Total | V31: Carbon Number | W31: n-Paraffins | X31: Isoparaffins | Y31: Aromatics | Z31: Naphthenes | AA31: Olefins | AB31: Oxygenates | AC31: Total
B32: 1 | K32: Run | L32: =Run_Plan!F14 -> R2 Catalyst Ni5CBV-3014 | P32: Sample | Q32: =Liq!$B$4 -> C1-S1 | V32: 1 | AE32: Run | AF32: =Run_Plan!F21 -> R6 Catalyst Cu5CBV720 | AJ32: Sample | AK32: =Liq!$B$4 -> C1-S1
B33: 2 | V33: 2
B34: 3 | V34: 3
B35: 4 | V35: 4
B36: 5 | V36: 5
B37: 6 | V37: 6
B38: 7 | V38: 7
B39: 8 | V39: 8
B40: 9 | V40: 9
B41: 10 | V41: 10
B42: 11 | V42: 11
B43: 12 | V43: 12
B44: 13 | V44: 13
... B46: 15 | V46: 15
B47: Total | V47: Total
H48: Total Unknowns | AB48: Total Unknowns
H49: Grand Total | AB49: Grand Total
O56: Unknowns | P56: =I48 -> 0 | AI56: Unknowns | AJ56: =AC48 -> 0
...

Sheet Gas
A1: Run Number | B1: =IF(Run_Plan!$B$1="", "", Run_Plan!$B$1) -> R6-C1-S1
A2: Run Objective | B2: =IF(Run_Plan!$B$2="","",Run_Plan!$B$2)
A3: Run Start Date | B3: =IF(Run_Plan!$B$3="", "", Run_Plan!$B$3) -> 45425.583 | D3: Duration of Sampling | E3: =IFERROR((B6-B5)*1440,"") -> 6
A4: Condition and Sample Number | B4: =IF(Liq!B4="", "", Liq!B4) -> C1-S1 | D4: Average Time-on-Stream | E4: =IFERROR(24*((B5+B6)/2-B3),"") -> 17.916667
A5: Sample Collection Started | B5: =IF(Liq!B5="","",Liq!B5) -> 45426.328 | D5: Average of 01i14FI01 | E5: 19.5
A6: Sample Collection Finished | B6: =IF(Liq!B6="", "", Liq!B6) -> 45426.332
A8: Calculation of Average Gas Flow into Each Reactor Over Sampling Duration
B9: R1 | C9: R2 | D9: R3 | E9: R4 | F9: R5 | G9: R6 | H9: R7 | I9: R8
B10: 02i2FIC01 | C10: 02i2FIC02 | D10: 02i2FIC03 | E10: 02i2FIC04 | F10: 02i2FIC05 | G10: 02i2FIC06 | H10: 02i2FIC07 | I10: 02i2FIC08
A11: Gas Feed Flow Rate [NmL/h] | B11: 3000 | C11: 3000 | E11: 3000 | F11: 3000 | G11: 3000 | H11: 3000 | I11: 3000 | J11: C mass% | K11: H mass% | L11: O mass% | M11: N mass%
A12: Total Gas Feed Flow Rate [g/h] | B12: =IFERROR($E$5*B11/SUM($B$11:$I$11),"") -> 2.7857143 | C12: =IFERROR($E$5*C11/SUM($B$11:$I$11),"") -> 2.7857143 | D12: =IFERROR($E$5*D11/SUM($B$11:$I$11),"") -> 0 | E12: =IFERROR($E$5*E11/SUM($B$11:$I$11),"") -> 2.7857143 | F12: =IFERROR($E$5*F11/SUM($B$11:$I$11),"") -> 2.7857143 | G12: =IFERROR($E$5*G11/SUM($B$11:$I$11),"") -> 2.7857143 | H12: =IFERROR($E$5*H11/SUM($B$11:$I$11),"") -> 2.7857143 | I12: =IFERROR($E$5*I11/SUM($B$11:$I$11),"") -> 2.7857143 | J12: 0 | K12: 100 | L12: 0 | M12: 0
A13: Flow Rate of H2 Contained [g/h] (Note 1) | B13: =IFERROR(B12*$B$37/100,"") -> 0 | C13: =IFERROR(C12*$B$37/100,"") -> 0 | D13: =IFERROR(D12*$B$37/100,"") -> 0 | E13: =IFERROR(E12*$B$37/100,"") -> 0 | F13: =IFERROR(F12*$B$37/100,"") -> 0 | G13: =IFERROR(G12*$B$37/100,"") -> 0 | H13: =IFERROR(H12*$B$37/100,"") -> 0 | I13: =IFERROR(I12*$B$37/100,"") -> 0 | J13: 85.627718 | K13: 14.372282 | L13: 0 | M13: 0
A14: Flow Rate of C2H4 Contained [g/h] (Note 1) | B14: =IFERROR(B12*$C$37/100,"") -> 0 | C14: =IFERROR(C12*$C$37/100,"") -> 0 | D14: =IFERROR(D12*$C$37/100,"") -> 0 | E14: =IFERROR(E12*$C$37/100,"") -> 0 | F14: =IFERROR(F12*$C$37/100,"") -> 0 | G14: =IFERROR(G12*$C$37/100,"") -> 0 | H14: =IFERROR(H12*$C$37/100,"") -> 0 | I14: =IFERROR(I12*$C$37/100,"") -> 0 | J14: 74.867543 | K14: 25.132457 | L14: 0 | M14: 0
A15: Flow Rate of CH4 Contained [g/h] (Note 1) | B15: =IFERROR(B12*$D$37/100,"") -> 0 | C15: =IFERROR(C12*$D$37/100,"") -> 0 | D15: =IFERROR(D12*$D$37/100,"") -> 0 | E15: =IFERROR(E12*$D$37/100,"") -> 0 | F15: =IFERROR(F12*$D$37/100,"") -> 0 | G15: =IFERROR(G12*$D$37/100,"") -> 0 | H15: =IFERROR(H12*$D$37/100,"") -> 0 | I15: =IFERROR(I12*$D$37/100,"") -> 0 | J15: 79.88693 | K15: 20.11307 | L15: 0 | M15: 0
A16: Flow Rate of C2H6 Contained [g/h] (Note 1) | B16: =IFERROR(B12*$E$37/100,"") -> 0 | C16: =IFERROR(C12*$E$37/100,"") -> 0 | D16: =IFERROR(D12*$E$37/100,"") -> 0 | E16: =IFERROR(E12*$E$37/100,"") -> 0 | F16: =IFERROR(F12*$E$37/100,"") -> 0 | G16: =IFERROR(G12*$E$37/100,"") -> 0 | H16: =IFERROR(H12*$E$37/100,"") -> 0 | I16: =IFERROR(I12*$E$37/100,"") -> 0 | J16: 0 | K16: 0 | L16: 0 | M16: 100
A17: Flow Rate of N2 Contained [g/h] (Note 1) | B17: =IFERROR(B12*$F$37/100,"") -> 0 | C17: =IFERROR(C12*$F$37/100,"") -> 0 | D17: =IFERROR(D12*$F$37/100,"") -> 0 | E17: =IFERROR(E12*$F$37/100,"") -> 0 | F17: =IFERROR(F12*$F$37/100,"") -> 0 | G17: =IFERROR(G12*$F$37/100,"") -> 0 | H17: =IFERROR(H12*$F$37/100,"") -> 0 | I17: =IFERROR(I12*$F$37/100,"") -> 0 | J17: 27.292145 | K17: 0 | L17: 72.707855 | M17: 0
A18: Flow Rate of CO2 Contained [g/h] (Note 1) | B18: =IFERROR(B12*$G$37/100,"") -> 0 | C18: =IFERROR(C12*$G$37/100,"") -> 0 | D18: =IFERROR(D12*$G$37/100,"") -> 0 | E18: =IFERROR(E12*$G$37/100,"") -> 0 | F18: =IFERROR(F12*$G$37/100,"") -> 0 | G18: =IFERROR(G12*$G$37/100,"") -> 0 | H18: =IFERROR(H12*$G$37/100,"") -> 0 | I18: =IFERROR(I12*$G$37/100,"") -> 0 | J18: 42.881114 | K18: 0 | L18: 57.118886 | M18: 0
A19: Flow Rate of CO Contained [g/h] (Note 1) | B19: =IFERROR(B12*$H$37/100,"") -> 0 | C19: =IFERROR(C12*$H$37/100,"") -> 0 | D19: =IFERROR(D12*$H$37/100,"") -> 0 | E19: =IFERROR(E12*$H$37/100,"") -> 0 | F19: =IFERROR(F12*$H$37/100,"") -> 0 | G19: =IFERROR(G12*$H$37/100,"") -> 0 | H19: =IFERROR(H12*$H$37/100,"") -> 0 | I19: =IFERROR(I12*$H$37/100,"") -> 0
A20: Flow Rate of Ar Contained [g/h] (Note 1) | B20: =IFERROR(B12*$I$37/100,"") -> 0.22890922 | C20: =IFERROR(C12*$I$37/100,"") -> 0.22890922 | D20: =IFERROR(D12*$I$37/100,"") -> 0 | E20: =IFERROR(E12*$I$37/100,"") -> 0.22890922 | F20: =IFERROR(F12*$I$37/100,"") -> 0.22890922 | G20: =IFERROR(G12*$I$37/100,"") -> 0.22890922 | H20: =IFERROR(H12*$I$37/100,"") -> 0.22890922 | I20: =IFERROR(I12*$I$37/100,"") -> 0.22890922
A21: Flow Rate of Mixed Gas Contained [g/h] | B21: =IFERROR(B12*$J$37/100,"") -> 2.5568051 | C21: =IFERROR(C12*$J$37/100,"") -> 2.5568051 | D21: =IFERROR(D12*$J$37/100,"") -> 0 | E21: =IFERROR(E12*$J$37/100,"") -> 2.5568051 | F21: =IFERROR(F12*$J$37/100,"") -> 2.5568051 | G21: =IFERROR(G12*$J$37/100,"") -> 2.5568051 | H21: =IFERROR(H12*$J$37/100,"") -> 2.5568051 | I21: =IFERROR(I12*$J$37/100,"") -> 2.5568051
A22: Flow Rate of Elemental Carbon Contained [g/h] | B22: =IFERROR(B14*$J13*0.01+B15*$J14*0.01+B16*$J15*0.01+B18*$J17*0.01+B19*$J18*0.01+B21*$J20*0.01,"") -> 0 | C22: =IFERROR(C14*$J13*0.01+C15*$J14*0.01+C16*$J15*0.01+C18*$J17*0.01+C19*$J18*0.01+C21*$J20*0.01,"") -> 0 | D22: =IFERROR(D14*$J13*0.01+D15*$J14*0.01+D16*$J15*0.01+D18*$J17*0.01+D19*$J18*0.01+D21*$J20*0.01,"") -> 0 | E22: =IFERROR(E14*$J13*0.01+E15*$J14*0.01+E16*$J15*0.01+E18*$J17*0.01+E19*$J18*0.01+E21*$J20*0.01,"") -> 0 | F22: =IFERROR(F14*$J13*0.01+F15*$J14*0.01+F16*$J15*0.01+F18*$J17*0.01+F19*$J18*0.01+F21*$J20*0.01,"") -> 0 | G22: =IFERROR(G14*$J13*0.01+G15*$J14*0.01+G16*$J15*0.01+G18*$J17*0.01+G19*$J18*0.01+G21*$J20*0.01,"") -> 0 | H22: =IFERROR(H14*$J13*0.01+H15*$J14*0.01+H16*$J15*0.01+H18*$J17*0.01+H19*$J18*0.01+H21*$J20*0.01,"") -> 0 | I22: =IFERROR(I14*$J13*0.01+I15*$J14*0.01+I16*$J15*0.01+I18*$J17*0.01+I19*$J18*0.01+I21*$J20*0.01,"") -> 0
A23: Flow Rate of Elemental Hydrogen Contained [g/h] | B23: =IFERROR(B13*$K12*0.01+B14*$K13*0.01+B15*$K14*0.01+B16*$K15*0.01+B21*$K20*0.01,"") -> 0 | C23: =IFERROR(C13*$K12*0.01+C14*$K13*0.01+C15*$K14*0.01+C16*$K15*0.01+C21*$K20*0.01,"") -> 0 | D23: =IFERROR(D13*$K12*0.01+D14*$K13*0.01+D15*$K14*0.01+D16*$K15*0.01+D21*$K20*0.01,"") -> 0 | E23: =IFERROR(E13*$K12*0.01+E14*$K13*0.01+E15*$K14*0.01+E16*$K15*0.01+E21*$K20*0.01,"") -> 0 | F23: =IFERROR(F13*$K12*0.01+F14*$K13*0.01+F15*$K14*0.01+F16*$K15*0.01+F21*$K20*0.01,"") -> 0 | G23: =IFERROR(G13*$K12*0.01+G14*$K13*0.01+G15*$K14*0.01+G16*$K15*0.01+G21*$K20*0.01,"") -> 0 | H23: =IFERROR(H13*$K12*0.01+H14*$K13*0.01+H15*$K14*0.01+H16*$K15*0.01+H21*$K20*0.01,"") -> 0 | I23: =IFERROR(I13*$K12*0.01+I14*$K13*0.01+I15*$K14*0.01+I16*$K15*0.01+I21*$K20*0.01,"") -> 0
A24: Flow Rate of Elemental Oxygen Contained [g/h] | B24: =IFERROR(B18*$L17*0.01+B19*$L18*0.01+B21*$L20*0.01,"") -> 0 | C24: =IFERROR(C18*$L17*0.01+C19*$L18*0.01+C21*$L20*0.01,"") -> 0 | D24: =IFERROR(D18*$L17*0.01+D19*$L18*0.01+D21*$L20*0.01,"") -> 0 | E24: =IFERROR(E18*$L17*0.01+E19*$L18*0.01+E21*$L20*0.01,"") -> 0 | F24: =IFERROR(F18*$L17*0.01+F19*$L18*0.01+F21*$L20*0.01,"") -> 0 | G24: =IFERROR(G18*$L17*0.01+G19*$L18*0.01+G21*$L20*0.01,"") -> 0 | H24: =IFERROR(H18*$L17*0.01+H19*$L18*0.01+H21*$L20*0.01,"") -> 0 | I24: =IFERROR(I18*$L17*0.01+I19*$L18*0.01+I21*$L20*0.01,"") -> 0
A25: Flow Rate of Elemental Nitrogen Contained [g/h] | B25: =IFERROR(B17+B21*$M20*0.01,"") -> 0 | C25: =IFERROR(C17+C21*$M20*0.01,"") -> 0 | D25: =IFERROR(D17+D21*$M20*0.01,"") -> 0 | E25: =IFERROR(E17+E21*$M20*0.01,"") -> 0 | F25: =IFERROR(F17+F21*$M20*0.01,"") -> 0 | G25: =IFERROR(G17+G21*$M20*0.01,"") -> 0 | H25: =IFERROR(H17+H21*$M20*0.01,"") -> 0 | I25: =IFERROR(I17+I21*$M20*0.01,"") -> 0
A26: Flow Rate of Elemental Argon Contained [g/h] | B26: =B20 -> 0.22890922 | C26: =C20 -> 0.22890922 | D26: =D20 -> 0 | E26: =E20 -> 0.22890922 | F26: =F20 -> 0.22890922 | G26: =G20 -> 0.22890922 | H26: =H20 -> 0.22890922 | I26: =I20 -> 0.22890922
A27: Total Flow Rate of Carbon Contained in Gas [g/h] | B27: =SUM(B22:I22) -> 0
A28: Total Flow Rate of Hydrogen Contained in Gas [g/h] | B28: =SUM(B23:I23) -> 0
A29: Total Flow Rate of Oxygen Contained in Gas [g/h] | B29: =SUM(B24:I24) -> 0
A30: Total Flow Rate of Nitrogen Contained in Gas [g/h] | B30: =SUM(B25:I25) -> 0
A31: Total Flow Rate of Argon Contained in Gas [g/h] | B31: =SUM(B26:I26) -> 1.6023645
A33: Verified Feed Gas Composition for This Condition
A34: Gas | B34: Hydrogen | C34: Ethylene | D34: Methane | E34: Ethane | F34: Nitrogen | G34: CO2 | H34: CO | I34: Argon | J34: Mixed gas | K34: Total
A35: Concentration [mol %] | I35: 4.3 | J35: 95.6 | K35: =SUM(B35:J35) -> 99.9
A36: Mol Wt | B36: 2.016 | C36: 28.054 | D36: 16.043 | E36: 30.07 | F36: 28.014 | G36: 44.009 | H36: 28.01 | I36: 39.948 | J36: =SUM(Run_Plan!B38:K38)/100 -> 20.069656
A37: Concentration [mass %] | B37: =IFERROR(100*B38/SUM($B$38:$J$38),"") -> 0 | C37: =IFERROR(100*C38/SUM($B$38:$J$38),"") -> 0 | D37: =IFERROR(100*D38/SUM($B$38:$J$38),"") -> 0 | E37: =IFERROR(100*E38/SUM($B$38:$J$38),"") -> 0 | F37: =IFERROR(100*F38/SUM($B$38:$J$38),"") -> 0 | G37: =IFERROR(100*G38/SUM($B$38:$J$38),"") -> 0 | H37: =IFERROR(100*H38/SUM($B$38:$J$38),"") -> 0 | I37: =IFERROR(100*I38/SUM($B$38:$J$38),"") -> 8.2172541 | J37: =IFERROR(100*J38/SUM($B$38:$J$38),"") -> 91.782746 | K37: =SUM(B37:J37) -> 100
A38: Calculating Mass % | B38: =B35*B36 -> 0 | C38: =C35*C36 -> 0 | D38: =D35*D36 -> 0 | E38: =E35*E36 -> 0 | F38: =F35*F36 -> 0 | G38: =G35*G36 -> 0 | H38: =H35*H36 -> 0 | I38: =I35*I36 -> 171.7764 | J38: =J35*J36 -> 1918.6591 | U38: =SUM(S8:S11) -> 0

Sheet R1_MB
A1: Run Number | C1: =IF(Run_Plan!$B$1="","",Run_Plan!$B$1) -> R6-C1-S1
A2: Run Objective | C2: =IF(Run_Plan!$B$2="","",Run_Plan!$B$2)
A3: Run Start Date | C3: =IF(Run_Plan!$B$3="","",Run_Plan!$B$3) -> 45425.583 | E3: Duration of Sampling | F3: =IFERROR((C6-C5)*1440,"") -> 6
A4: Condition and Sample Number | C4: =IF(Liq!B4="", "", Liq!B4) -> C1-S1 | E4: Average Time-on-Stream | F4: =IFERROR(24*((C5+C6)/2-C3),"") -> 17.916667
A5: Sample Collection Started | C5: =IF(Liq!B5="","",Liq!B5) -> 45426.328 | E5: Average Ar Flow to Reactor | F5: =Gas!B20 -> 0.22890922 | H5: GC injection time lies outside sampling duration - check!
A6: Sample Collection Finished | C6: =IF(Liq!B6="","",Liq!B6) -> 45426.332 | H6: {=MIN(IF(D16:XFD16<>0,D16:XFD16))} -> 0 | I6: {=MAX(IF(D16:XFD16<>0,D16:XFD16))} -> 0 | K6: =IF(AND(H7=TRUE,I7=TRUE),"Pass","Fail") -> Fail
H7: =IF(Liq!B3>='R1_MB'!H6,FALSE,TRUE) -> FALSE | I7: =IF(Liq!B6<='R1_MB'!I6,FALSE,TRUE) -> TRUE
A8: Flow Rate of Liquid Feed [g/h] | C8: =Liq!B13 -> 0.5
A9: Flow Rate of Gas Feed [g/h] | C9: =IFERROR(Gas!B12-Gas!B20,"") -> 2.5568051 | D9: (Without Ar)
A10: Flow Rate of HC TLP [g/h] | C10: =Liq!B40 -> 0
A11: Flow Rate of Aqueous TLP [g/h] | C11: =Liq!B41 -> 0
A12: Flow Rate of Gas Product [g/h] | C12: =SUM(C52:C74,C76:C80) -> 2.5902325 | D12: (Without Ar)
A13: Mass Balance Closure [%] | C13: =IFERROR(100*(C12+C11+C10)/(C9+C8),"") -> 84.736596
A15: GC Analysis Rep Number for the Reactor
A16: Date and Time
A17: Cumulative Time Lapsed [min] | E17: =IF(E15="", "", (E16-$D$16)*1440) | F17: =IF(F15="", "", (F16-$D$16)*1440) | G17: =IF(G15="", "", (G16-$D$16)*1440) | H17: =IF(H15="", "", (H16-$D$16)*1440) | I17: =IF(I15="", "", (I16-$D$16)*1440) | J17: =IF(J15="", "", (J16-$D$16)*1440) | K17: =IF(K15="", "", (K16-$D$16)*1440) | L17: =IF(L15="", "", (L16-$D$16)*1440) | ... AB17: =IF(AB15="", "", (AB16-$D$16)*1440)
A18: Time Elapsed Between Two Reps [min] | E18: =IF(E17="", "", E17-D17) | F18: =IF(F17="", "", F17-E17) | G18: =IF(G17="", "", G17-F17) | H18: =IF(H17="", "", H17-G17) | I18: =IF(I17="", "", I17-H17) | J18: =IF(J17="", "", J17-I17) | K18: =IF(K17="", "", K17-J17) | L18: =IF(L17="", "", L17-K17) | ... AB18: =IF(AB17="", "", AB17-AA17)
A19: Normalized Mol% | B19: Mol Wt
A20: Methane | B20: 16.04 | D20: 2.562962 | E20: 2.589108 | F20: 2.590509 | G20: 2.592991 | H20: 2.648659 | I20: 2.654462 | J20: 2.639587 | K20: 2.647193 | L20: 2.610692 | M20: 2.616605 | N20: 2.607807 | O20: 2.616981 | AC20: =IFERROR(_xlfn.STDEV.S(E20:AB20),"") -> 0.024369838 | AD20: =IFERROR(AVERAGE(E20:AB20),"") -> 2.6195085 | AE20: =IFERROR(AD20+(2*AC20),"") -> 2.6682482
A21: Ethane | B21: 30.07 | D21: 0.002815 | E21: 0.006575 | F21: 0.006072 | G21: 0.005461 | H21: 0.001359 | I21: 0.001282 | J21: 0.001245 | K21: 0.001226 | L21: 0.00142 | M21: 0.001308 | N21: 0.001327 | O21: 0.001296 | AC21: =IFERROR(_xlfn.STDEV.S(E21:AB21),"") -> 0.0022231592 | AD21: =IFERROR(AVERAGE(E21:AB21),"") -> 0.0025973636 | AE21: =IFERROR(AD21+(2*AC21),"") -> 0.007043682
A22: Ethylene | B22: 28.05 | D22: 1.574832 | E22: 1.625097 | F22: 1.629188 | G22: 1.629592 | H22: 1.664953 | I22: 1.668622 | J22: 1.662825 | K22: 1.663445 | L22: 1.648668 | M22: 1.651386 | N22: 1.645274 | O22: 1.652523 | AC22: =IFERROR(_xlfn.STDEV.S(E22:AB22),"") -> 0.015528506 | AD22: =IFERROR(AVERAGE(E22:AB22),"") -> 1.6492339 | AE22: =IFERROR(AD22+(2*AC22),"") -> 1.6802909
A23: Propane | B23: 44.1 | D23: 0 | E23: 0 | F23: 0 | G23: 0 | H23: 0 | I23: 0 | J23: 0 | K23: 0 | L23: 0 | M23: 0 | N23: 0 | O23: 0 | AC23: =IFERROR(_xlfn.STDEV.S(E23:AB23),"") -> 0 | AD23: =IFERROR(AVERAGE(E23:AB23),"") -> 0 | AE23: =IFERROR(AD23+(2*AC23),"") -> 0
A24: Propylene | B24: 42.08 | D24: 0.001619 | E24: 0.002609 | F24: 0.001866 | G24: 0.001515 | H24: 0 | I24: 0 | J24: 0 | K24: 0 | L24: 0 | M24: 0 | N24: 0 | O24: 0 | AC24: =IFERROR(_xlfn.STDEV.S(E24:AB24),"") -> 0.0009655172 | AD24: =IFERROR(AVERAGE(E24:AB24),"") -> 0.00054454545 | AE24: =IFERROR(AD24+(2*AC24),"") -> 0.0024755799
A25: Butane | B25: 58.12 | D25: 0.00061 | E25: 0.000532 | F25: 0.000407 | G25: 0.000357 | H25: 0 | I25: 0 | J25: 0 | K25: 0 | L25: 0 | M25: 0 | N25: 0 | O25: 0 | AC25: =IFERROR(_xlfn.STDEV.S(E25:AB25),"") -> 0.00020577406 | AD25: =IFERROR(AVERAGE(E25:AB25),"") -> 0.00011781818 | AE25: =IFERROR(AD25+(2*AC25),"") -> 0.0005293663
A26: Pentane | B26: 72.15 | D26: 0 | E26: 0 | F26: 0 | G26: 0 | H26: 0 | I26: 0 | J26: 0 | K26: 0 | L26: 0 | M26: 0 | N26: 0 | O26: 0 | AC26: =IFERROR(_xlfn.STDEV.S(E26:AB26),"") -> 0 | AD26: =IFERROR(AVERAGE(E26:AB26),"") -> 0 | AE26: =IFERROR(AD26+(2*AC26),"") -> 0
A27: C6s (Isomers of hexane?) | B27: 86.18 | D27: 0.000757 | E27: 0.001431 | F27: 0.000372 | G27: 0.000248 | H27: 0 | I27: 0 | J27: 0 | K27: 0 | L27: 0 | M27: 0 | N27: 0 | O27: 0 | AC27: =IFERROR(_xlfn.STDEV.S(E27:AB27),"") -> 0.00043188317 | AD27: =IFERROR(AVERAGE(E27:AB27),"") -> 0.00018645455 | AE27: =IFERROR(AD27+(2*AC27),"") -> 0.0010502209
A28: Hexane | B28: 86.18 | D28: 0 | E28: 0 | F28: 0 | G28: 0 | H28: 0 | I28: 0 | J28: 0 | K28: 0 | L28: 0 | M28: 0 | N28: 0 | O28: 0 | AC28: =IFERROR(_xlfn.STDEV.S(E28:AB28),"") -> 0 | AD28: =IFERROR(AVERAGE(E28:AB28),"") -> 0 | AE28: =IFERROR(AD28+(2*AC28),"") -> 0
A29: C4 | B29: 58.12 | D29: 0 | E29: 0.013741 | F29: 0.011877 | G29: 0.012342 | H29: 0 | I29: 0 | J29: 0 | K29: 0 | L29: 0 | M29: 0 | N29: 0 | O29: 0 | AC29: =IFERROR(_xlfn.STDEV.S(E29:AB29),"") -> 0.0059262692 | AD29: =IFERROR(AVERAGE(E29:AB29),"") -> 0.0034509091 | AE29: =IFERROR(AD29+(2*AC29),"") -> 0.015303447
A30: C5 | B30: 72.15 | D30: 0 | E30: 0 | F30: 0 | G30: 0 | H30: 0 | I30: 0 | J30: 0 | K30: 0 | L30: 0 | M30: 0 | N30: 0 | O30: 0 | AC30: =IFERROR(_xlfn.STDEV.S(E30:AB30),"") -> 0 | AD30: =IFERROR(AVERAGE(E30:AB30),"") -> 0 | AE30: =IFERROR(AD30+(2*AC30),"") -> 0
A31: C6 | B31: 86.18 | D31: 0.000757 | E31: 0.001431 | F31: 0.000372 | G31: 0.000248 | H31: 0 | I31: 0 | J31: 0 | K31: 0 | L31: 0 | M31: 0 | N31: 0 | O31: 0 | AC31: =IFERROR(_xlfn.STDEV.S(E31:AB31),"") -> 0.00043188317 | AD31: =IFERROR(AVERAGE(E31:AB31),"") -> 0.00018645455 | AE31: =IFERROR(AD31+(2*AC31),"") -> 0.0010502209
... A48: N2 | B48: 28.0134 | D48: 58.127076 | E48: 58.736901 | F48: 58.835983 | G48: 58.879727 | H48: 58.714565 | I48: 58.8611 | J48: 57.869145 | K48: 58.498389 | L48: 59.328628 | M48: 59.297252 | N48: 59.315772 | O48: 59.405 | AC48: =IFERROR(_xlfn.STDEV.S(E48:AB48),"") -> 0.45366612 | AD48: =IFERROR(AVERAGE(E48:AB48),"") -> 58.885678 | AE48: =IFERROR(AD48+(2*AC48),"") -> 59.793011
AC49: =IFERROR(_xlfn.STDEV.S(E49:AB49),"") | AD49: =IFERROR(AVERAGE(E49:AB49),"") | AE49: =IFERROR(AD49+(2*AC49),"")
A51: Mass Flow Rates of Each Molecule | C51: Avg Flow Rate | AC51: C" Mass Flow Rate (g/h) | AD51: Number of "C' Atom
A52: =IF(A20="", "", CONCATENATE(A20, " [g/h]")) -> Methane [g/h] | C52: =IFERROR(AVERAGE(D52:AB52), "") -> 0.054414622 | D52: =IF(SUM(D20:D48)=0, "", (D20*$B20/(D$43*$B$43))*$F$5) -> 0.042570468 | E52: =IF(SUM(E20:E48)=0, "", (E20*$B20/(E$43*$B$43))*$F$5) -> 0.055183722 | F52: =IF(SUM(F20:F48)=0, "", (F20*$B20/(F$43*$B$43))*$F$5) -> 0.055345956 | G52: =IF(SUM(G20:G48)=0, "", (G20*$B20/(G$43*$B$43))*$F$5) -> 0.055118511 | H52: =IF(SUM(H20:H48)=0, "", (H20*$B20/(H$43*$B$43))*$F$5) -> 0.056217087 | I52: =IF(SUM(I20:I48)=0, "", (I20*$B20/(I$43*$B$43))*$F$5) -> 0.05585956 | J52: =IF(SUM(J20:J48)=0, "", (J20*$B20/(J$43*$B$43))*$F$5) -> 0.05679517 | K52: =IF(SUM(K20:K48)=0, "", (K20*$B20/(K$43*$B$43))*$F$5) -> 0.056440777 | ... AB52: =IF(SUM(AB20:AB48)=0, "", (AB20*$B20/(AB$43*$B$43))*$F$5) | AC52: =(12.011*$AD52/$B20)*$C52 -> 0.04074651 | AD52: 1
A53: =IF(A21="", "", CONCATENATE(A21, " [g/h]")) -> Ethane [g/h] | C53: =IFERROR(AVERAGE(D53:AB53), "") -> 0.00010213859 | D53: =IF(SUM(D21:D49)=0, "", (D21*$B21/(D$43*$B$43))*$F$5) -> 8.76544e-05 | E53: =IF(SUM(E21:E49)=0, "", (E21*$B21/(E$43*$B$43))*$F$5) -> 0.00026271547 | F53: =IF(SUM(F21:F49)=0, "", (F21*$B21/(F$43*$B$43))*$F$5) -> 0.00024319891 | G53: =IF(SUM(G21:G49)=0, "", (G21*$B21/(G$43*$B$43))*$F$5) -> 0.00021761945 | H53: =IF(SUM(H21:H49)=0, "", (H21*$B21/(H$43*$B$43))*$F$5) -> 5.4074288e-05 | I53: =IF(SUM(I21:I49)=0, "", (I21*$B21/(I$43*$B$43))*$F$5) -> 5.0575256e-05 | J53: =IF(SUM(J21:J49)=0, "", (J21*$B21/(J$43*$B$43))*$F$5) -> 5.0219668e-05 | K53: =IF(SUM(K21:K49)=0, "", (K21*$B21/(K$43*$B$43))*$F$5) -> 4.9003479e-05 | ... AB53: =IF(SUM(AB21:AB49)=0, "", (AB21*$B21/(AB$43*$B$43))*$F$5) | AC53: =(12.011*$AD53/$B21)*$C53 -> 8.1595385e-05 | AD53: 2
A54: =IF(A22="", "", CONCATENATE(A22, " [g/h]")) -> Ethylene [g/h] | C54: =IFERROR(AVERAGE(D54:AB54), "") -> 0.059816454 | D54: =IF(SUM(D22:D50)=0, "", (D22*$B22/(D$43*$B$43))*$F$5) -> 0.045743458 | E54: =IF(SUM(E22:E50)=0, "", (E22*$B22/(E$43*$B$43))*$F$5) -> 0.06057154 | F54: =IF(SUM(F22:F50)=0, "", (F22*$B22/(F$43*$B$43))*$F$5) -> 0.060869606 | G54: =IF(SUM(G22:G50)=0, "", (G22*$B22/(G$43*$B$43))*$F$5) -> 0.060576454 | H54: =IF(SUM(H22:H50)=0, "", (H22*$B22/(H$43*$B$43))*$F$5) -> 0.061797765 | I54: =IF(SUM(I22:I50)=0, "", (I22*$B22/(I$43*$B$43))*$F$5) -> 0.061405528 | J54: =IF(SUM(J22:J50)=0, "", (J22*$B22/(J$43*$B$43))*$F$5) -> 0.06256774 | K54: =IF(SUM(K22:K50)=0, "", (K22*$B22/(K$43*$B$43))*$F$5) -> 0.062021794 | ... AB54: =IF(SUM(AB22:AB50)=0, "", (AB22*$B22/(AB$43*$B$43))*$F$5) | AC54: =(12.011*$AD54/$B22)*$C54 -> 0.051226769 | AD54: 2
A55: =IF(A23="", "", CONCATENATE(A23, " [g/h]")) -> Propane [g/h] | C55: =IFERROR(AVERAGE(D55:AB55), "") -> 0 | D55: =IF(SUM(D23:D51)=0, "", (D23*$B23/(D$43*$B$43))*$F$5) -> 0 | E55: =IF(SUM(E23:E51)=0, "", (E23*$B23/(E$43*$B$43))*$F$5) -> 0 | F55: =IF(SUM(F23:F51)=0, "", (F23*$B23/(F$43*$B$43))*$F$5) -> 0 | G55: =IF(SUM(G23:G51)=0, "", (G23*$B23/(G$43*$B$43))*$F$5) -> 0 | H55: =IF(SUM(H23:H51)=0, "", (H23*$B23/(H$43*$B$43))*$F$5) -> 0 | I55: =IF(SUM(I23:I51)=0, "", (I23*$B23/(I$43*$B$43))*$F$5) -> 0 | J55: =IF(SUM(J23:J51)=0, "", (J23*$B23/(J$43*$B$43))*$F$5) -> 0 | K55: =IF(SUM(K23:K51)=0, "", (K23*$B23/(K$43*$B$43))*$F$5) -> 0 | ... AB55: =IF(SUM(AB23:AB51)=0, "", (AB23*$B23/(AB$43*$B$43))*$F$5) | AC55: =(12.011*$AD55/$B23)*$C55 -> 0 | AD55: 3
A56: =IF(A24="", "", CONCATENATE(A24, " [g/h]")) -> Propylene [g/h] | C56: =IFERROR(AVERAGE(D56:AB56), "") -> 3.3792094e-05 | D56: =IF(SUM(D24:D52)=0, "", (D24*$B24/(D$43*$B$43))*$F$5) -> 7.0547962e-05 | E56: =IF(SUM(E24:E52)=0, "", (E24*$B24/(E$43*$B$43))*$F$5) -> 0.00014588353 | F56: =IF(SUM(F24:F52)=0, "", (F24*$B24/(F$43*$B$43))*$F$5) -> 0.00010458847 | G56: =IF(SUM(G24:G52)=0, "", (G24*$B24/(G$43*$B$43))*$F$5) -> 8.4485167e-05 | H56: =IF(SUM(H24:H52)=0, "", (H24*$B24/(H$43*$B$43))*$F$5) -> 0 | I56: =IF(SUM(I24:I52)=0, "", (I24*$B24/(I$43*$B$43))*$F$5) -> 0 | J56: =IF(SUM(J24:J52)=0, "", (J24*$B24/(J$43*$B$43))*$F$5) -> 0 | K56: =IF(SUM(K24:K52)=0, "", (K24*$B24/(K$43*$B$43))*$F$5) -> 0 | ... AB56: =IF(SUM(AB24:AB52)=0, "", (AB24*$B24/(AB$43*$B$43))*$F$5) | AC56: =(12.011*$AD56/$B24)*$C56 -> 2.8936087e-05 | AD56: 3
A57: =IF(A25="", "", CONCATENATE(A25, " [g/h]")) -> Butane [g/h] | C57: =IFERROR(AVERAGE(D57:AB57), "") -> 1.1400291e-05 | D57: =IF(SUM(D25:D53)=0, "", (D25*$B25/(D$43*$B$43))*$F$5) -> 3.6712785e-05 | E57: =IF(SUM(E25:E53)=0, "", (E25*$B25/(E$43*$B$43))*$F$5) -> 4.1085984e-05 | F57: =IF(SUM(F25:F53)=0, "", (F25*$B25/(F$43*$B$43))*$F$5) -> 3.1507681e-05 | G57: =IF(SUM(G25:G53)=0, "", (G25*$B25/(G$43*$B$43))*$F$5) -> 2.7497039e-05 | H57: =IF(SUM(H25:H53)=0, "", (H25*$B25/(H$43*$B$43))*$F$5) -> 0 | I57: =IF(SUM(I25:I53)=0, "", (I25*$B25/(I$43*$B$43))*$F$5) -> 0 | J57: =IF(SUM(J25:J53)=0, "", (J25*$B25/(J$43*$B$43))*$F$5) -> 0 | K57: =IF(SUM(K25:K53)=0, "", (K25*$B25/(K$43*$B$43))*$F$5) -> 0 | ... AB57: =IF(SUM(AB25:AB53)=0, "", (AB25*$B25/(AB$43*$B$43))*$F$5) | AC57: =(12.011*$AD57/$B25)*$C57 -> 9.4238742e-06 | AD57: 4
A58: =IF(A26="", "", CONCATENATE(A26, " [g/h]")) -> Pentane [g/h] | C58: =IFERROR(AVERAGE(D58:AB58), "") -> 0 | D58: =IF(SUM(D26:D54)=0, "", (D26*$B26/(D$43*$B$43))*$F$5) -> 0 | E58: =IF(SUM(E26:E54)=0, "", (E26*$B26/(E$43*$B$43))*$F$5) -> 0 | F58: =IF(SUM(F26:F54)=0, "", (F26*$B26/(F$43*$B$43))*$F$5) -> 0 | G58: =IF(SUM(G26:G54)=0, "", (G26*$B26/(G$43*$B$43))*$F$5) -> 0 | H58: =IF(SUM(H26:H54)=0, "", (H26*$B26/(H$43*$B$43))*$F$5) -> 0 | I58: =IF(SUM(I26:I54)=0, "", (I26*$B26/(I$43*$B$43))*$F$5) -> 0 | J58: =IF(SUM(J26:J54)=0, "", (J26*$B26/(J$43*$B$43))*$F$5) -> 0 | K58: =IF(SUM(K26:K54)=0, "", (K26*$B26/(K$43*$B$43))*$F$5) -> 0 | ... AB58: =IF(SUM(AB26:AB54)=0, "", (AB26*$B26/(AB$43*$B$43))*$F$5) | AC58: =(12.011*$AD58/$B26)*$C58 -> 0 | AD58: 5
...

Sheet R2_MB
A1: Run Number | C1: ='R1_MB'!C1 -> R6-C1-S1
A2: Run Objective | C2: ='R1_MB'!C2
A3: Run Start Date | C3: =Run_Plan!$B$3 -> 45425.583 | E3: Duration of Sampling | F3: =(C6-C5)*1440 -> 6
A4: Condition and Sample Number | C4: =Liq!B4 -> C1-S1 | E4: Average Time-on-Stream | F4: =24*((C5+C6)/2-C3) -> 17.916667
A5: Sample Collection Started | C5: =Liq!B5 -> 45426.328 | E5: Average Ar Flow to Reactor | F5: =Gas!C20 -> 0.22890922 | H5: GC injection time lies outside sampling duration - check!
A6: Sample Collection Finished | C6: =Liq!B6 -> 45426.332 | H6: {=MIN(IF(D16:XFD16<>0,D16:XFD16))} -> 0 | I6: {=MAX(IF(D16:XFD16<>0,D16:XFD16))} -> 0 | K6: =IF(AND(H7=TRUE,I7=TRUE),"Pass","Fail") -> Pass
H7: =IF(Liq!C3>'R1_MB'!H6,"NA",TRUE) -> TRUE | I7: =IF(Liq!C6<'R1_MB'!I6,"NA",TRUE) -> TRUE
A8: Flow Rate of Liquid Feed [g/h] | C8: =Liq!C13 -> 0.5
A9: Flow Rate of Gas Feed [g/h] | C9: =IFERROR(Gas!C12-Gas!C20,"") -> 2.5568051 | D9: (Without Ar)
A10: Flow Rate of HC TLP [g/h] | C10: =Liq!C40 -> 0
A11: Flow Rate of Aqueous TLP [g/h] | C11: =Liq!C41 -> 0
A12: Flow Rate of Gas Product [g/h] | C12: =SUM(C52:C74,C76:C80) -> 2.6335059 | D12: (Without Ar)
A13: Mass Balance Closure [%] | C13: =IFERROR(100*(C12+C11+C10)/(C9+C8),"") -> 86.152235
A15: GC Analysis Rep Number for the Reactor
A16: Date and Time
A17: Cumulative Time Lapsed [min] | D17: =IF(D15="", "", (D16-$D$16)*1440) | E17: =IF(E15="", "", (E16-$D$16)*1440) | F17: =IF(F15="", "", (F16-$D$16)*1440) | G17: =IF(G15="", "", (G16-$D$16)*1440) | H17: =IF(H15="", "", (H16-$D$16)*1440) | I17: =IF(I15="", "", (I16-$D$16)*1440) | J17: =IF(J15="", "", (J16-$D$16)*1440) | K17: =IF(K15="", "", (K16-$D$16)*1440) | ... AB17: =IF(AB15="", "", (AB16-$D$16)*1440)
A18: Time Elapsed Between Two Reps [min] | E18: =IF(E17="", "", E17-D17) | F18: =IF(F17="", "", F17-E17) | G18: =IF(G17="", "", G17-F17) | H18: =IF(H17="", "", H17-G17) | I18: =IF(I17="", "", I17-H17) | J18: =IF(J17="", "", J17-I17) | K18: =IF(K17="", "", K17-J17) | L18: =IF(L17="", "", L17-K17) | ... AB18: =IF(AB17="", "", AB17-AA17)
A19: Normalized Mol% | B19: Mol Wt
A20: Methane | B20: 16.04 | D20: 2.574339 | E20: 2.587217 | F20: 2.595544 | G20: 2.638684 | H20: 2.647556 | I20: 2.638358 | J20: 2.634007 | K20: 2.640019 | L20: 2.60212 | M20: 2.606419 | N20: 2.600359 | O20: 2.605023 | AC20: =IFERROR(_xlfn.STDEV.S(E20:AB20),"") -> 0.021849486 | AD20: =IFERROR(AVERAGE(E20:AB20),"") -> 2.6177551 | AE20: =IFERROR(AD20+(2*AC20),"") -> 2.6614541
A21: Ethane | B21: 30.07 | D21: 0.005571 | E21: 0.003871 | F21: 0.003555 | G21: 0.003425 | H21: 0.006508 | I21: 0.001957 | J21: 0.001765 | K21: 0.001507 | L21: 0.00186 | M21: 0.001739 | N21: 0.001708 | O21: 0.001776 | AC21: =IFERROR(_xlfn.STDEV.S(E21:AB21),"") -> 0.0015311813 | AD21: =IFERROR(AVERAGE(E21:AB21),"") -> 0.0026973636 | AE21: =IFERROR(AD21+(2*AC21),"") -> 0.0057597263
A22: Ethylene | B22: 28.05 | D22: 1.631944 | E22: 1.632676 | F22: 1.63932 | G22: 1.669326 | H22: 1.670753 | I22: 1.657297 | J22: 1.65821 | K22: 1.652863 | L22: 1.630481 | M22: 1.642331 | N22: 1.635397 | O22: 1.641103 | AC22: =IFERROR(_xlfn.STDEV.S(E22:AB22),"") -> 0.014290445 | AD22: =IFERROR(AVERAGE(E22:AB22),"") -> 1.6481597 | AE22: =IFERROR(AD22+(2*AC22),"") -> 1.6767406
A23: Propane | B23: 44.1 | D23: 0 | E23: 0 | F23: 0 | G23: 0 | H23: 0 | I23: 0 | J23: 0 | K23: 0 | L23: 0 | M23: 0 | N23: 0 | O23: 0 | AC23: =IFERROR(_xlfn.STDEV.S(E23:AB23),"") -> 0 | AD23: =IFERROR(AVERAGE(E23:AB23),"") -> 0 | AE23: =IFERROR(AD23+(2*AC23),"") -> 0
A24: Propylene | B24: 42.08 | D24: 0.002221 | E24: 0.001668 | F24: 0.001127 | G24: 0.000848 | H24: 0.001746 | I24: 0.000368 | J24: 0.000308 | K24: 0 | L24: 0 | M24: 0 | N24: 0 | O24: 0 | AC24: =IFERROR(_xlfn.STDEV.S(E24:AB24),"") -> 0.00068602045 | AD24: =IFERROR(AVERAGE(E24:AB24),"") -> 0.00055136364 | AE24: =IFERROR(AD24+(2*AC24),"") -> 0.0019234045
A25: Butane | B25: 58.12 | D25: 0.000431 | E25: 0.000285 | F25: 0 | G25: 0 | H25: 0.000386 | I25: 0 | J25: 0 | K25: 0 | L25: 0 | M25: 0 | N25: 0 | O25: 0.000248 | AC25: =IFERROR(_xlfn.STDEV.S(E25:AB25),"") -> 0.00014661062 | AD25: =IFERROR(AVERAGE(E25:AB25),"") -> 8.3545455e-05 | AE25: =IFERROR(AD25+(2*AC25),"") -> 0.00037676669
A26: Pentane | B26: 72.15 | D26: 0 | E26: 0 | F26: 0 | G26: 0 | H26: 0 | I26: 0 | J26: 0 | K26: 0 | L26: 0 | M26: 0 | N26: 0 | O26: 0 | AC26: =IFERROR(_xlfn.STDEV.S(E26:AB26),"") -> 0 | AD26: =IFERROR(AVERAGE(E26:AB26),"") -> 0 | AE26: =IFERROR(AD26+(2*AC26),"") -> 0
A27: C6s (Isomers of hexane?) | B27: 86.18 | D27: 0 | E27: 0 | F27: 0 | G27: 0 | H27: 0 | I27: 0 | J27: 0 | K27: 0 | L27: 0 | M27: 0 | N27: 0 | O27: 0 | AC27: =IFERROR(_xlfn.STDEV.S(E27:AB27),"") -> 0 | AD27: =IFERROR(AVERAGE(E27:AB27),"") -> 0 | AE27: =IFERROR(AD27+(2*AC27),"") -> 0
A28: Hexane | B28: 86.18 | D28: 0 | E28: 0 | F28: 0 | G28: 0 | H28: 0 | I28: 0 | J28: 0 | K28: 0 | L28: 0 | M28: 0 | N28: 0 | O28: 0 | AC28: =IFERROR(_xlfn.STDEV.S(E28:AB28),"") -> 0 | AD28: =IFERROR(AVERAGE(E28:AB28),"") -> 0 | AE28: =IFERROR(AD28+(2*AC28),"") -> 0
A29: C4 | B29: 58.12 | D29: 0.000554 | E29: 0.006184 | F29: 0.00574 | G29: 0.006484 | H29: 0.014515 | I29: 0.006765 | J29: 0.001083 | K29: 0.000498 | L29: 0.000538 | M29: 0.000388 | N29: 0 | O29: 0.000324 | AC29: =IFERROR(_xlfn.STDEV.S(E29:AB29),"") -> 0.0045529839 | AD29: =IFERROR(AVERAGE(E29:AB29),"") -> 0.0038653636 | AE29: =IFERROR(AD29+(2*AC29),"") -> 0.012971331
A30: C5 | B30: 72.15 | D30: 0 | E30: 0 | F30: 0 | G30: 0 | H30: 0 | I30: 0 | J30: 0 | K30: 0 | L30: 0 | M30: 0 | N30: 0 | O30: 0 | AC30: =IFERROR(_xlfn.STDEV.S(E30:AB30),"") -> 0 | AD30: =IFERROR(AVERAGE(E30:AB30),"") -> 0 | AE30: =IFERROR(AD30+(2*AC30),"") -> 0
A31: C6 | B31: 86.18 | D31: 0 | E31: 0.000406 | F31: 0 | G31: 0 | H31: 0 | I31: 0 | J31: 0 | K31: 0 | L31: 0 | M31: 0 | N31: 0 | O31: 0 | AC31: =IFERROR(_xlfn.STDEV.S(E31:AB31),"") -> 0.00012241361 | AD31: =IFERROR(AVERAGE(E31:AB31),"") -> 3.6909091e-05 | AE31: =IFERROR(AD31+(2*AC31),"") -> 0.0002817363
... A48: N2 | B48: 28.0134 | D48: 58.459293 | E48: 58.673376 | F48: 58.795353 | G48: 58.744627 | H48: 58.681742 | I48: 59.088477 | J48: 58.615517 | K48: 58.46575 | L48: 59.488699 | M48: 59.378947 | N48: 59.4715 | O48: 59.591121 | AC48: =IFERROR(_xlfn.STDEV.S(E48:AB48),"") -> 0.41355861 | AD48: =IFERROR(AVERAGE(E48:AB48),"") -> 58.999555 | AE48: =IFERROR(AD48+(2*AC48),"") -> 59.826673
A51: Mass Flow Rates of Each Molecule | C51: Avg Flow Rate | AC51: C" Mass Flow Rate (g/h) | AD51: Number of "C' Atom
A52: =IF(A20="", "", CONCATENATE(A20, " [g/h]")) -> Methane [g/h] | C52: =IFERROR(AVERAGE(D52:AB52), "") -> 0.055214854 | D52: =IF(SUM(D20:D48)=0, "", (D20*$B20/(D$43*$B$43))*$F$5) -> 0.049140291 | E52: =IF(SUM(E20:E48)=0, "", (E20*$B20/(E$43*$B$43))*$F$5) -> 0.055140528 | F52: =IF(SUM(F20:F48)=0, "", (F20*$B20/(F$43*$B$43))*$F$5) -> 0.055345167 | G52: =IF(SUM(G20:G48)=0, "", (G20*$B20/(G$43*$B$43))*$F$5) -> 0.056085488 | H52: =IF(SUM(H20:H48)=0, "", (H20*$B20/(H$43*$B$43))*$F$5) -> 0.056364105 | I52: =IF(SUM(I20:I48)=0, "", (I20*$B20/(I$43*$B$43))*$F$5) -> 0.056032779 | J52: =IF(SUM(J20:J48)=0, "", (J20*$B20/(J$43*$B$43))*$F$5) -> 0.056299052 | K52: =IF(SUM(K20:K48)=0, "", (K20*$B20/(K$43*$B$43))*$F$5) -> 0.056447071 | ... AB52: =IF(SUM(AB20:AB48)=0, "", (AB20*$B20/(AB$43*$B$43))*$F$5) | AC52: =(12.011*$AD52/$B20)*$C52 -> 0.041345737 | AD52: 1
A53: =IF(A21="", "", CONCATENATE(A21, " [g/h]")) -> Ethane [g/h] | C53: =IFERROR(AVERAGE(D53:AB53), "") -> 0.00011534176 | D53: =IF(SUM(D21:D49)=0, "", (D21*$B21/(D$43*$B$43))*$F$5) -> 0.00019935825 | E53: =IF(SUM(E21:E49)=0, "", (E21*$B21/(E$43*$B$43))*$F$5) -> 0.00015466438 | F53: =IF(SUM(F21:F49)=0, "", (F21*$B21/(F$43*$B$43))*$F$5) -> 0.00014210847 | G53: =IF(SUM(G21:G49)=0, "", (G21*$B21/(G$43*$B$43))*$F$5) -> 0.00013647489 | H53: =IF(SUM(H21:H49)=0, "", (H21*$B21/(H$43*$B$43))*$F$5) -> 0.00025973715 | I53: =IF(SUM(I21:I49)=0, "", (I21*$B21/(I$43*$B$43))*$F$5) -> 7.7916301e-05 | J53: =IF(SUM(J21:J49)=0, "", (J21*$B21/(J$43*$B$43))*$F$5) -> 7.0722553e-05 | K53: =IF(SUM(K21:K49)=0, "", (K21*$B21/(K$43*$B$43))*$F$5) -> 6.0405527e-05 | ... AB53: =IF(SUM(AB21:AB49)=0, "", (AB21*$B21/(AB$43*$B$43))*$F$5) | AC53: =(12.011*$AD53/$B21)*$C53 -> 9.2142992e-05 | AD53: 2
A54: =IF(A22="", "", CONCATENATE(A22, " [g/h]")) -> Ethylene [g/h] | C54: =IFERROR(AVERAGE(D54:AB54), "") -> 0.060823958 | D54: =IF(SUM(D22:D50)=0, "", (D22*$B22/(D$43*$B$43))*$F$5) -> 0.054476066 | E54: =IF(SUM(E22:E50)=0, "", (E22*$B22/(E$43*$B$43))*$F$5) -> 0.060850839 | F54: =IF(SUM(F22:F50)=0, "", (F22*$B22/(F$43*$B$43))*$F$5) -> 0.061128473 | G54: =IF(SUM(G22:G50)=0, "", (G22*$B22/(G$43*$B$43))*$F$5) -> 0.062048713 | H54: =IF(SUM(H22:H50)=0, "", (H22*$B22/(H$43*$B$43))*$F$5) -> 0.062201121 | I54: =IF(SUM(I22:I50)=0, "", (I22*$B22/(I$43*$B$43))*$F$5) -> 0.061551307 | J54: =IF(SUM(J22:J50)=0, "", (J22*$B22/(J$43*$B$43))*$F$5) -> 0.061980088 | K54: =IF(SUM(K22:K50)=0, "", (K22*$B22/(K$43*$B$43))*$F$5) -> 0.0618016 | ... AB54: =IF(SUM(AB22:AB50)=0, "", (AB22*$B22/(AB$43*$B$43))*$F$5) | AC54: =(12.011*$AD54/$B22)*$C54 -> 0.052089595 | AD54: 2
A55: =IF(A23="", "", CONCATENATE(A23, " [g/h]")) -> Propane [g/h] | C55: =IFERROR(AVERAGE(D55:AB55), "") -> 0 | D55: =IF(SUM(D23:D51)=0, "", (D23*$B23/(D$43*$B$43))*$F$5) -> 0 | E55: =IF(SUM(E23:E51)=0, "", (E23*$B23/(E$43*$B$43))*$F$5) -> 0 | F55: =IF(SUM(F23:F51)=0, "", (F23*$B23/(F$43*$B$43))*$F$5) -> 0 | G55: =IF(SUM(G23:G51)=0, "", (G23*$B23/(G$43*$B$43))*$F$5) -> 0 | H55: =IF(SUM(H23:H51)=0, "", (H23*$B23/(H$43*$B$43))*$F$5) -> 0 | I55: =IF(SUM(I23:I51)=0, "", (I23*$B23/(I$43*$B$43))*$F$5) -> 0 | J55: =IF(SUM(J23:J51)=0, "", (J23*$B23/(J$43*$B$43))*$F$5) -> 0 | K55: =IF(SUM(K23:K51)=0, "", (K23*$B23/(K$43*$B$43))*$F$5) -> 0 | ... AB55: =IF(SUM(AB23:AB51)=0, "", (AB23*$B23/(AB$43*$B$43))*$F$5) | AC55: =(12.011*$AD55/$B23)*$C55 -> 0 | AD55: 3
A56: =IF(A24="", "", CONCATENATE(A24, " [g/h]")) -> Propylene [g/h] | C56: =IFERROR(AVERAGE(D56:AB56), "") -> 3.750867e-05 | D56: =IF(SUM(D24:D52)=0, "", (D24*$B24/(D$43*$B$43))*$F$5) -> 0.00011122231 | E56: =IF(SUM(E24:E52)=0, "", (E24*$B24/(E$43*$B$43))*$F$5) -> 9.3262161e-05 | F56: =IF(SUM(F24:F52)=0, "", (F24*$B24/(F$43*$B$43))*$F$5) -> 6.3044411e-05 | G56: =IF(SUM(G24:G52)=0, "", (G24*$B24/(G$43*$B$43))*$F$5) -> 4.7285756e-05 | H56: =IF(SUM(H24:H52)=0, "", (H24*$B24/(H$43*$B$43))*$F$5) -> 9.7515369e-05 | I56: =IF(SUM(I24:I52)=0, "", (I24*$B24/(I$43*$B$43))*$F$5) -> 2.0503482e-05 | J56: =IF(SUM(J24:J52)=0, "", (J24*$B24/(J$43*$B$43))*$F$5) -> 1.7270553e-05 | K56: =IF(SUM(K24:K52)=0, "", (K24*$B24/(K$43*$B$43))*$F$5) -> 0 | ... AB56: =IF(SUM(AB24:AB52)=0, "", (AB24*$B24/(AB$43*$B$43))*$F$5) | AC56: =(12.011*$AD56/$B24)*$C56 -> 3.2118582e-05 | AD56: 3
A57: =IF(A25="", "", CONCATENATE(A25, " [g/h]")) -> Butane [g/h] | C57: =IFERROR(AVERAGE(D57:AB57), "") -> 8.3934399e-06 | D57: =IF(SUM(D25:D53)=0, "", (D25*$B25/(D$43*$B$43))*$F$5) -> 2.9810585e-05 | E57: =IF(SUM(E25:E53)=0, "", (E25*$B25/(E$43*$B$43))*$F$5) -> 2.2009195e-05 | F57: =IF(SUM(F25:F53)=0, "", (F25*$B25/(F$43*$B$43))*$F$5) -> 0 | G57: =IF(SUM(G25:G53)=0, "", (G25*$B25/(G$43*$B$43))*$F$5) -> 0 | H57: =IF(SUM(H25:H53)=0, "", (H25*$B25/(H$43*$B$43))*$F$5) -> 2.9775976e-05 | I57: =IF(SUM(I25:I53)=0, "", (I25*$B25/(I$43*$B$43))*$F$5) -> 0 | J57: =IF(SUM(J25:J53)=0, "", (J25*$B25/(J$43*$B$43))*$F$5) -> 0 | K57: =IF(SUM(K25:K53)=0, "", (K25*$B25/(K$43*$B$43))*$F$5) -> 0 | ... AB57: =IF(SUM(AB25:AB53)=0, "", (AB25*$B25/(AB$43*$B$43))*$F$5) | AC57: =(12.011*$AD57/$B25)*$C57 -> 6.9383074e-06 | AD57: 4
A58: =IF(A26="", "", CONCATENATE(A26, " [g/h]")) -> Pentane [g/h] | C58: =IFERROR(AVERAGE(D58:AB58), "") -> 0 | D58: =IF(SUM(D26:D54)=0, "", (D26*$B26/(D$43*$B$43))*$F$5) -> 0 | E58: =IF(SUM(E26:E54)=0, "", (E26*$B26/(E$43*$B$43))*$F$5) -> 0 | F58: =IF(SUM(F26:F54)=0, "", (F26*$B26/(F$43*$B$43))*$F$5) -> 0 | G58: =IF(SUM(G26:G54)=0, "", (G26*$B26/(G$43*$B$43))*$F$5) -> 0 | H58: =IF(SUM(H26:H54)=0, "", (H26*$B26/(H$43*$B$43))*$F$5) -> 0 | I58: =IF(SUM(I26:I54)=0, "", (I26*$B26/(I$43*$B$43))*$F$5) -> 0 | J58: =IF(SUM(J26:J54)=0, "", (J26*$B26/(J$43*$B$43))*$F$5) -> 0 | K58: =IF(SUM(K26:K54)=0, "", (K26*$B26/(K$43*$B$43))*$F$5) -> 0 | ... AB58: =IF(SUM(AB26:AB54)=0, "", (AB26*$B26/(AB$43*$B$43))*$F$5) | AC58: =(12.011*$AD58/$B26)*$C58 -> 0 | AD58: 5
A59: =IF(A27="", "", CONCATENATE(A27, " [g/h]")) -> C6s (Isomers of hexane?) [g/h] | C59: =IFERROR(AVERAGE(D59:AB59), "") -> 0 | D59: =IF(SUM(D27:D55)=0, "", (D27*$B27/(D$43*$B$43))*$F$5) -> 0 | E59: =IF(SUM(E27:E55)=0, "", (E27*$B27/(E$43*$B$43))*$F$5) -> 0 | F59: =IF(SUM(F27:F55)=0, "", (F27*$B27/(F$43*$B$43))*$F$5) -> 0 | G59: =IF(SUM(G27:G55)=0, "", (G27*$B27/(G$43*$B$43))*$F$5) -> 0 | H59: =IF(SUM(H27:H55)=0, "", (H27*$B27/(H$43*$B$43))*$F$5) -> 0 | I59: =IF(SUM(I27:I55)=0, "", (I27*$B27/(I$43*$B$43))*$F$5) -> 0 | J59: =IF(SUM(J27:J55)=0, "", (J27*$B27/(J$43*$B$43))*$F$5) -> 0 | K59: =IF(SUM(K27:K55)=0, "", (K27*$B27/(K$43*$B$43))*$F$5) -> 0 | ... AB59: =IF(SUM(AB27:AB55)=0, "", (AB27*$B27/(AB$43*$B$43))*$F$5) | AC59: =(12.011*$AD59/$B27)*$C59 -> 0 | AD59: 6
...

Sheet R3_MB
A1: Run Number | C1: ='R2_MB'!C1 -> R6-C1-S1
A2: Run Objective | C2: ='R2_MB'!C2
A3: Run Start Date | C3: =Run_Plan!$B$3 -> 45425.583 | E3: Duration of Sampling | F3: =(C6-C5)*1440 -> 6
A4: Condition and Sample Number | C4: =Liq!B4 -> C1-S1 | E4: Average Time-on-Stream | F4: =24*((C5+C6)/2-C3) -> 17.916667
A5: Sample Collection Started | C5: =Liq!B5 -> 45426.328 | E5: Average Ar Flow to Reactor | F5: =Gas!D20 -> 0 | H5: GC injection time lies outside sampling duration - check!
A6: Sample Collection Finished | C6: =Liq!B6 -> 45426.332 | H6: {=MIN(IF(D16:XFD16<>0,D16:XFD16))} -> 0 | I6: {=MAX(IF(D16:XFD16<>0,D16:XFD16))} -> 0 | K6: =IF(AND(H7=TRUE,I7=TRUE),"Pass","Fail") -> Pass
H7: =IF(Liq!D3>'R1_MB'!H6,"NA",TRUE) -> TRUE | I7: =IF(Liq!D6<'R1_MB'!I6,"NA",TRUE) -> TRUE
A8: Flow Rate of Liquid Feed [g/h] | C8: =Liq!D13
A9: Flow Rate of Gas Feed [g/h] | C9: =IFERROR(Gas!D12-Gas!D20,"") -> 0 | D9: (Without Ar)
A10: Flow Rate of HC TLP [g/h] | C10: =Liq!D40 -> 0
A11: Flow Rate of Aqueous TLP [g/h] | C11: =Liq!D41
A12: Flow Rate of Gas Product [g/h] | C12: =SUM(C52:C74,C76:C80) -> 0 | D12: (Without Ar)
A13: Mass Balance Closure [%] | C13: =IFERROR(100*(C12+C11+C10)/(C9+C8),"")
A15: GC Analysis Rep Number for the Reactor
A16: Date and Time
A17: Cumulative Time Lapsed [min] | D17: =IF(D15="", "", (D16-$D$16)*1440) | E17: =IF(E15="", "", (E16-$D$16)*1440) | F17: =IF(F15="", "", (F16-$D$16)*1440) | G17: =IF(G15="", "", (G16-$D$16)*1440) | I17: =IF(I15="", "", (I16-$D$16)*1440) | J17: =IF(J15="", "", (J16-$D$16)*1440) | K17: =IF(K15="", "", (K16-$D$16)*1440) | L17: =IF(L15="", "", (L16-$D$16)*1440) | M17: =IF(M15="", "", (M16-$D$16)*1440) | N17: =IF(N15="", "", (N16-$D$16)*1440) | O17: =IF(O15="", "", (O16-$D$16)*1440) | P17: =IF(P15="", "", (P16-$D$16)*1440) | ... AB17: =IF(AB15="", "", (AB16-$D$16)*1440)
A18: Time Elapsed Between Two Reps [min] | E18: =IF(E17="", "", E17-D17) | F18: =IF(F17="", "", F17-E17) | G18: =IF(G17="", "", G17-F17) | I18: =IF(I17="", "", I17-H17) | J18: =IF(J17="", "", J17-I17) | K18: =IF(K17="", "", K17-J17) | L18: =IF(L17="", "", L17-K17) | M18: =IF(M17="", "", M17-L17) | N18: =IF(N17="", "", N17-M17) | O18: =IF(O17="", "", O17-N17) | P18: =IF(P17="", "", P17-O17) | ... AB18: =IF(AB17="", "", AB17-AA17)
A19: Normalized Mol% | B19: Mol Wt
A20: Methane | B20: 16.04
A21: Ethane | B21: 30.07
A22: Ethylene | B22: 28.05
A23: Propane | B23: 44.1
A24: Propylene | B24: 42.08
A25: Butane | B25: 58.12
A26: Pentane | B26: 72.15
A27: C6s (Isomers of hexane?) | B27: 86.18
A28: Hexane | B28: 86.18
A29: C4 | B29: 58.12
A30: C5 | B30: 72.15
A31: C6 | B31: 86.18
... A48: N2 | B48: 28.0134
A51: Mass Flow Rates of Each Molecule | C51: Avg Flow Rate | AC51: C" Mass Flow Rate (g/h) | AD51: Number of "C' Atom
A52: =IF(A20="", "", CONCATENATE(A20, " [g/h]")) -> Methane [g/h] | C52: =IFERROR(AVERAGE(D52:AB52), "") | D52: =IF(SUM(D20:D48)=0, "", (D20*$B20/(D$43*$B$43))*$F$5) | E52: =IF(SUM(E20:E48)=0, "", (E20*$B20/(E$43*$B$43))*$F$5) | F52: =IF(SUM(F20:F48)=0, "", (F20*$B20/(F$43*$B$43))*$F$5) | G52: =IF(SUM(G20:G48)=0, "", (G20*$B20/(G$43*$B$43))*$F$5) | H52: =IF(SUM(H20:H48)=0, "", (H20*$B20/(H$43*$B$43))*$F$5) | I52: =IF(SUM(I20:I48)=0, "", (I20*$B20/(I$43*$B$43))*$F$5) | J52: =IF(SUM(J20:J48)=0, "", (J20*$B20/(J$43*$B$43))*$F$5) | K52: =IF(SUM(K20:K48)=0, "", (K20*$B20/(K$43*$B$43))*$F$5) | ... AB52: =IF(SUM(AB20:AB48)=0, "", (AB20*$B20/(AB$43*$B$43))*$F$5) | AC52: =(12.011*$AD52/$B20)*$C52 -> #VALUE! | AD52: 1
A53: =IF(A21="", "", CONCATENATE(A21, " [g/h]")) -> Ethane [g/h] | C53: =IFERROR(AVERAGE(D53:AB53), "") | D53: =IF(SUM(D21:D49)=0, "", (D21*$B21/(D$43*$B$43))*$F$5) | E53: =IF(SUM(E21:E49)=0, "", (E21*$B21/(E$43*$B$43))*$F$5) | F53: =IF(SUM(F21:F49)=0, "", (F21*$B21/(F$43*$B$43))*$F$5) | G53: =IF(SUM(G21:G49)=0, "", (G21*$B21/(G$43*$B$43))*$F$5) | H53: =IF(SUM(H21:H49)=0, "", (H21*$B21/(H$43*$B$43))*$F$5) | I53: =IF(SUM(I21:I49)=0, "", (I21*$B21/(I$43*$B$43))*$F$5) | J53: =IF(SUM(J21:J49)=0, "", (J21*$B21/(J$43*$B$43))*$F$5) | K53: =IF(SUM(K21:K49)=0, "", (K21*$B21/(K$43*$B$43))*$F$5) | ... AB53: =IF(SUM(AB21:AB49)=0, "", (AB21*$B21/(AB$43*$B$43))*$F$5) | AC53: =(12.011*$AD53/$B21)*$C53 -> #VALUE! | AD53: 2
A54: =IF(A22="", "", CONCATENATE(A22, " [g/h]")) -> Ethylene [g/h] | C54: =IFERROR(AVERAGE(D54:AB54), "") | D54: =IF(SUM(D22:D50)=0, "", (D22*$B22/(D$43*$B$43))*$F$5) | E54: =IF(SUM(E22:E50)=0, "", (E22*$B22/(E$43*$B$43))*$F$5) | F54: =IF(SUM(F22:F50)=0, "", (F22*$B22/(F$43*$B$43))*$F$5) | G54: =IF(SUM(G22:G50)=0, "", (G22*$B22/(G$43*$B$43))*$F$5) | H54: =IF(SUM(H22:H50)=0, "", (H22*$B22/(H$43*$B$43))*$F$5) | I54: =IF(SUM(I22:I50)=0, "", (I22*$B22/(I$43*$B$43))*$F$5) | J54: =IF(SUM(J22:J50)=0, "", (J22*$B22/(J$43*$B$43))*$F$5) | K54: =IF(SUM(K22:K50)=0, "", (K22*$B22/(K$43*$B$43))*$F$5) | ... AB54: =IF(SUM(AB22:AB50)=0, "", (AB22*$B22/(AB$43*$B$43))*$F$5) | AC54: =(12.011*$AD54/$B22)*$C54 -> #VALUE! | AD54: 2
A55: =IF(A23="", "", CONCATENATE(A23, " [g/h]")) -> Propane [g/h] | C55: =IFERROR(AVERAGE(D55:AB55), "") | D55: =IF(SUM(D23:D51)=0, "", (D23*$B23/(D$43*$B$43))*$F$5) | E55: =IF(SUM(E23:E51)=0, "", (E23*$B23/(E$43*$B$43))*$F$5) | F55: =IF(SUM(F23:F51)=0, "", (F23*$B23/(F$43*$B$43))*$F$5) | G55: =IF(SUM(G23:G51)=0, "", (G23*$B23/(G$43*$B$43))*$F$5) | H55: =IF(SUM(H23:H51)=0, "", (H23*$B23/(H$43*$B$43))*$F$5) | I55: =IF(SUM(I23:I51)=0, "", (I23*$B23/(I$43*$B$43))*$F$5) | J55: =IF(SUM(J23:J51)=0, "", (J23*$B23/(J$43*$B$43))*$F$5) | K55: =IF(SUM(K23:K51)=0, "", (K23*$B23/(K$43*$B$43))*$F$5) | ... AB55: =IF(SUM(AB23:AB51)=0, "", (AB23*$B23/(AB$43*$B$43))*$F$5) | AC55: =(12.011*$AD55/$B23)*$C55 -> #VALUE! | AD55: 3
A56: =IF(A24="", "", CONCATENATE(A24, " [g/h]")) -> Propylene [g/h] | C56: =IFERROR(AVERAGE(D56:AB56), "") | D56: =IF(SUM(D24:D52)=0, "", (D24*$B24/(D$43*$B$43))*$F$5) | E56: =IF(SUM(E24:E52)=0, "", (E24*$B24/(E$43*$B$43))*$F$5) | F56: =IF(SUM(F24:F52)=0, "", (F24*$B24/(F$43*$B$43))*$F$5) | G56: =IF(SUM(G24:G52)=0, "", (G24*$B24/(G$43*$B$43))*$F$5) | H56: =IF(SUM(H24:H52)=0, "", (H24*$B24/(H$43*$B$43))*$F$5) | I56: =IF(SUM(I24:I52)=0, "", (I24*$B24/(I$43*$B$43))*$F$5) | J56: =IF(SUM(J24:J52)=0, "", (J24*$B24/(J$43*$B$43))*$F$5) | K56: =IF(SUM(K24:K52)=0, "", (K24*$B24/(K$43*$B$43))*$F$5) | ... AB56: =IF(SUM(AB24:AB52)=0, "", (AB24*$B24/(AB$43*$B$43))*$F$5) | AC56: =(12.011*$AD56/$B24)*$C56 -> #VALUE! | AD56: 3
A57: =IF(A25="", "", CONCATENATE(A25, " [g/h]")) -> Butane [g/h] | C57: =IFERROR(AVERAGE(D57:AB57), "") | D57: =IF(SUM(D25:D53)=0, "", (D25*$B25/(D$43*$B$43))*$F$5) | E57: =IF(SUM(E25:E53)=0, "", (E25*$B25/(E$43*$B$43))*$F$5) | F57: =IF(SUM(F25:F53)=0, "", (F25*$B25/(F$43*$B$43))*$F$5) | G57: =IF(SUM(G25:G53)=0, "", (G25*$B25/(G$43*$B$43))*$F$5) | H57: =IF(SUM(H25:H53)=0, "", (H25*$B25/(H$43*$B$43))*$F$5) | I57: =IF(SUM(I25:I53)=0, "", (I25*$B25/(I$43*$B$43))*$F$5) | J57: =IF(SUM(J25:J53)=0, "", (J25*$B25/(J$43*$B$43))*$F$5) | K57: =IF(SUM(K25:K53)=0, "", (K25*$B25/(K$43*$B$43))*$F$5) | ... AB57: =IF(SUM(AB25:AB53)=0, "", (AB25*$B25/(AB$43*$B$43))*$F$5) | AC57: =(12.011*$AD57/$B25)*$C57 -> #VALUE! | AD57: 4
